function delayError(milliseconds) {
  return new Promise((_resolve, reject) => {
    setTimeout(() => {
      reject(new Error(`Error after ${milliseconds}ms`))
    }, milliseconds)
  })
}

async function errorCaught() {
  try {
    return await delayError(1000)
  } catch (err) {
    console.error(`Error caught by the async function: ${err.message}`)
  }
}

errorCaught().catch(err =>
  console.error(`Error caught by the caller: ${err.message}`)
)
